[2025-02-26T15:43:06.595+0000] {local_task_job_runner.py:123} INFO - ::group::Pre task execution logs
[2025-02-26T15:43:06.602+0000] {taskinstance.py:2614} INFO - Dependencies all met for dep_context=non-requeueable deps ti=<TaskInstance: data_cleaning_ecommerce_postgres.clean_data_task manual__2025-02-26T15:43:02.812066+00:00 [queued]>
[2025-02-26T15:43:06.605+0000] {taskinstance.py:2614} INFO - Dependencies all met for dep_context=requeueable deps ti=<TaskInstance: data_cleaning_ecommerce_postgres.clean_data_task manual__2025-02-26T15:43:02.812066+00:00 [queued]>
[2025-02-26T15:43:06.606+0000] {taskinstance.py:2867} INFO - Starting attempt 1 of 1
[2025-02-26T15:43:06.611+0000] {taskinstance.py:2890} INFO - Executing <Task(PythonOperator): clean_data_task> on 2025-02-26 15:43:02.812066+00:00
[2025-02-26T15:43:06.616+0000] {warnings.py:112} WARNING - /home/***/.local/lib/python3.12/site-packages/***/task/task_runner/standard_task_runner.py:70: DeprecationWarning: This process (pid=100) is multi-threaded, use of fork() may lead to deadlocks in the child.
  pid = os.fork()

[2025-02-26T15:43:06.617+0000] {standard_task_runner.py:72} INFO - Started process 115 to run task
[2025-02-26T15:43:06.618+0000] {standard_task_runner.py:104} INFO - Running: ['***', 'tasks', 'run', 'data_cleaning_ecommerce_postgres', 'clean_data_task', 'manual__2025-02-26T15:43:02.812066+00:00', '--job-id', '42', '--raw', '--subdir', 'DAGS_FOLDER/data_cleaning_ecommerce_postgres.py', '--cfg-path', '/tmp/tmphhnzc2uy']
[2025-02-26T15:43:06.618+0000] {standard_task_runner.py:105} INFO - Job 42: Subtask clean_data_task
[2025-02-26T15:43:06.640+0000] {task_command.py:467} INFO - Running <TaskInstance: data_cleaning_ecommerce_postgres.clean_data_task manual__2025-02-26T15:43:02.812066+00:00 [running]> on host b93a72659cb5
[2025-02-26T15:43:06.671+0000] {taskinstance.py:3134} INFO - Exporting env vars: AIRFLOW_CTX_DAG_OWNER='***' AIRFLOW_CTX_DAG_ID='data_cleaning_ecommerce_postgres' AIRFLOW_CTX_TASK_ID='clean_data_task' AIRFLOW_CTX_EXECUTION_DATE='2025-02-26T15:43:02.812066+00:00' AIRFLOW_CTX_TRY_NUMBER='1' AIRFLOW_CTX_DAG_RUN_ID='manual__2025-02-26T15:43:02.812066+00:00'
[2025-02-26T15:43:06.672+0000] {logging_mixin.py:190} INFO - Task instance is in running state
[2025-02-26T15:43:06.672+0000] {logging_mixin.py:190} INFO -  Previous state of the Task instance: queued
[2025-02-26T15:43:06.672+0000] {logging_mixin.py:190} INFO - Current task name:clean_data_task state:running start_date:2025-02-26 15:43:06.603132+00:00
[2025-02-26T15:43:06.672+0000] {logging_mixin.py:190} INFO - Dag name:data_cleaning_ecommerce_postgres and current dag run status:running
[2025-02-26T15:43:06.672+0000] {taskinstance.py:732} INFO - ::endgroup::
[2025-02-26T15:43:06.673+0000] {data_cleaning_ecommerce_postgres.py:256} INFO - Starting e-commerce data cleaning process
[2025-02-26T15:43:06.673+0000] {data_cleaning_ecommerce_postgres.py:61} INFO - Establishing database connection
[2025-02-26T15:43:06.673+0000] {data_cleaning_ecommerce_postgres.py:70} INFO - Connecting to PostgreSQL at data-postgres:5432/datawarehouse
[2025-02-26T15:43:06.673+0000] {data_cleaning_ecommerce_postgres.py:71} INFO - User: datauser
[2025-02-26T15:43:06.673+0000] {data_cleaning_ecommerce_postgres.py:72} INFO - Password: datapass
[2025-02-26T15:43:06.675+0000] {data_cleaning_ecommerce_postgres.py:80} INFO - Database connection established successfully
[2025-02-26T15:43:06.675+0000] {data_cleaning_ecommerce_postgres.py:97} INFO - Extracting data from ecommerce_orders table
[2025-02-26T15:43:06.676+0000] {warnings.py:112} WARNING - /opt/***/dags/data_cleaning_ecommerce_postgres.py:100: UserWarning: pandas only supports SQLAlchemy connectable (engine/connection) or database string URI or sqlite3 DBAPI2 connection. Other DBAPI2 objects are not tested. Please consider using SQLAlchemy.
  df = pd.read_sql(query, conn)

[2025-02-26T15:43:06.678+0000] {data_cleaning_ecommerce_postgres.py:101} INFO - Successfully extracted 103 records
[2025-02-26T15:43:06.678+0000] {logging_mixin.py:190} INFO - Original DataFrame:
[2025-02-26T15:43:06.684+0000] {logging_mixin.py:190} INFO -    order_id customer        order_date     product  quantity   price
0      1001    alice        2021/01/15      Laptop       1.0  1200.0
1      1002     Bob         15-01-2021  smartphone       2.0   800.0
2      1003  charlie  January 15, 2021      Tablet       NaN   400.0
3      1002      Bob        15/01/2021  Smartphone       2.0   800.0
4      1004    David        2021.01.16     laptop        1.0  1200.0
[2025-02-26T15:43:06.684+0000] {data_cleaning_ecommerce_postgres.py:265} INFO - Starting data transformation pipeline
[2025-02-26T15:43:06.684+0000] {data_cleaning_ecommerce_postgres.py:122} INFO - Handling missing values
[2025-02-26T15:43:06.684+0000] {data_cleaning_ecommerce_postgres.py:125} INFO - Found 20 missing quantity values and 14 missing price values
[2025-02-26T15:43:06.686+0000] {data_cleaning_ecommerce_postgres.py:130} INFO - Missing values handled successfully
[2025-02-26T15:43:06.686+0000] {data_cleaning_ecommerce_postgres.py:144} INFO - Removing duplicate records
[2025-02-26T15:43:06.687+0000] {data_cleaning_ecommerce_postgres.py:148} INFO - Removed 2 duplicate records
[2025-02-26T15:43:06.688+0000] {data_cleaning_ecommerce_postgres.py:162} INFO - Standardizing data formats
[2025-02-26T15:43:06.691+0000] {warnings.py:112} WARNING - /opt/***/dags/data_cleaning_ecommerce_postgres.py:167: SettingWithCopyWarning: 
A value is trying to be set on a copy of a slice from a DataFrame.
Try using .loc[row_indexer,col_indexer] = value instead

See the caveats in the documentation: https://pandas.pydata.org/pandas-docs/stable/user_guide/indexing.html#returning-a-view-versus-a-copy
  df['order_date'] = pd.to_datetime(df['order_date'], errors='coerce')

[2025-02-26T15:43:06.691+0000] {data_cleaning_ecommerce_postgres.py:171} INFO - Date standardization: 72 new invalid dates detected
[2025-02-26T15:43:06.692+0000] {warnings.py:112} WARNING - /opt/***/dags/data_cleaning_ecommerce_postgres.py:173: SettingWithCopyWarning: 
A value is trying to be set on a copy of a slice from a DataFrame.
Try using .loc[row_indexer,col_indexer] = value instead

See the caveats in the documentation: https://pandas.pydata.org/pandas-docs/stable/user_guide/indexing.html#returning-a-view-versus-a-copy
  df['customer'] = df['customer'].str.strip().str.title()

[2025-02-26T15:43:06.692+0000] {warnings.py:112} WARNING - /opt/***/dags/data_cleaning_ecommerce_postgres.py:174: SettingWithCopyWarning: 
A value is trying to be set on a copy of a slice from a DataFrame.
Try using .loc[row_indexer,col_indexer] = value instead

See the caveats in the documentation: https://pandas.pydata.org/pandas-docs/stable/user_guide/indexing.html#returning-a-view-versus-a-copy
  df['product'] = df['product'].str.strip().str.lower().str.title()

[2025-02-26T15:43:06.692+0000] {data_cleaning_ecommerce_postgres.py:176} INFO - Data formats standardized successfully
[2025-02-26T15:43:06.692+0000] {data_cleaning_ecommerce_postgres.py:190} INFO - Adding computed columns
[2025-02-26T15:43:06.693+0000] {warnings.py:112} WARNING - /opt/***/dags/data_cleaning_ecommerce_postgres.py:191: SettingWithCopyWarning: 
A value is trying to be set on a copy of a slice from a DataFrame.
Try using .loc[row_indexer,col_indexer] = value instead

See the caveats in the documentation: https://pandas.pydata.org/pandas-docs/stable/user_guide/indexing.html#returning-a-view-versus-a-copy
  df['total_cost'] = df['quantity'] * df['price']

[2025-02-26T15:43:06.693+0000] {data_cleaning_ecommerce_postgres.py:192} INFO - Added 'total_cost' column
[2025-02-26T15:43:06.693+0000] {data_cleaning_ecommerce_postgres.py:271} INFO - Data transformation completed
[2025-02-26T15:43:06.693+0000] {logging_mixin.py:190} INFO - 
Cleaned DataFrame:
[2025-02-26T15:43:06.697+0000] {logging_mixin.py:190} INFO -    order_id customer order_date     product  quantity   price  total_cost
0      1001    Alice 2021-01-15      Laptop       1.0  1200.0      1200.0
1      1002      Bob        NaT  Smartphone       2.0   800.0      1600.0
2      1003  Charlie        NaT      Tablet       3.0   400.0      1200.0
4      1004    David        NaT      Laptop       1.0  1200.0      1200.0
5      1005      Eve        NaT      Tablet       3.0   400.0      1200.0
[2025-02-26T15:43:06.697+0000] {data_cleaning_ecommerce_postgres.py:206} INFO - Running data quality checks with Great Expectations
[2025-02-26T15:43:06.697+0000] {data_cleaning_ecommerce_postgres.py:288} ERROR - Data cleaning process failed: module 'great_expectations' has no attribute 'from_pandas'
[2025-02-26T15:43:06.698+0000] {taskinstance.py:3313} ERROR - Task failed with exception
Traceback (most recent call last):
  File "/home/airflow/.local/lib/python3.12/site-packages/airflow/models/taskinstance.py", line 768, in _execute_task
    result = _execute_callable(context=context, **execute_callable_kwargs)
             ^^^^^^^^^^^^^^^^^^^^^^^^^^^^^^^^^^^^^^^^^^^^^^^^^^^^^^^^^^^^^
  File "/home/airflow/.local/lib/python3.12/site-packages/airflow/models/taskinstance.py", line 734, in _execute_callable
    return ExecutionCallableRunner(
           ^^^^^^^^^^^^^^^^^^^^^^^^
  File "/home/airflow/.local/lib/python3.12/site-packages/airflow/utils/operator_helpers.py", line 252, in run
    return self.func(*args, **kwargs)
           ^^^^^^^^^^^^^^^^^^^^^^^^^^
  File "/home/airflow/.local/lib/python3.12/site-packages/airflow/models/baseoperator.py", line 424, in wrapper
    return func(self, *args, **kwargs)
           ^^^^^^^^^^^^^^^^^^^^^^^^^^^
  File "/home/airflow/.local/lib/python3.12/site-packages/airflow/operators/python.py", line 238, in execute
    return_value = self.execute_callable()
                   ^^^^^^^^^^^^^^^^^^^^^^^
  File "/home/airflow/.local/lib/python3.12/site-packages/airflow/operators/python.py", line 256, in execute_callable
    return runner.run(*self.op_args, **self.op_kwargs)
           ^^^^^^^^^^^^^^^^^^^^^^^^^^^^^^^^^^^^^^^^^^^
  File "/home/airflow/.local/lib/python3.12/site-packages/airflow/utils/operator_helpers.py", line 252, in run
    return self.func(*args, **kwargs)
           ^^^^^^^^^^^^^^^^^^^^^^^^^^
  File "/opt/airflow/dags/data_cleaning_ecommerce_postgres.py", line 276, in load_and_clean_data
    quality_check_passed = run_data_quality_checks(df_clean)
                           ^^^^^^^^^^^^^^^^^^^^^^^^^^^^^^^^^
  File "/opt/airflow/dags/data_cleaning_ecommerce_postgres.py", line 207, in run_data_quality_checks
    ge_df = ge.from_pandas(df)
            ^^^^^^^^^^^^^^
AttributeError: module 'great_expectations' has no attribute 'from_pandas'
[2025-02-26T15:43:06.703+0000] {logging_mixin.py:190} INFO - Task instance in failure state
[2025-02-26T15:43:06.703+0000] {logging_mixin.py:190} INFO - Task start:2025-02-26 15:43:06.603132+00:00 end:2025-02-26 15:43:06.702856+00:00 duration:0.099724
[2025-02-26T15:43:06.703+0000] {logging_mixin.py:190} INFO - Task:<Task(PythonOperator): clean_data_task> dag:<DAG: data_cleaning_ecommerce_postgres> dagrun:<DagRun data_cleaning_ecommerce_postgres @ 2025-02-26 15:43:02.812066+00:00: manual__2025-02-26T15:43:02.812066+00:00, state:running, queued_at: 2025-02-26 15:43:02.826454+00:00. externally triggered: True>
[2025-02-26T15:43:06.703+0000] {logging_mixin.py:190} INFO - Failure caused by module 'great_expectations' has no attribute 'from_pandas'
[2025-02-26T15:43:06.703+0000] {taskinstance.py:1226} INFO - Marking task as FAILED. dag_id=data_cleaning_ecommerce_postgres, task_id=clean_data_task, run_id=manual__2025-02-26T15:43:02.812066+00:00, execution_date=20250226T154302, start_date=20250226T154306, end_date=20250226T154306
[2025-02-26T15:43:06.714+0000] {taskinstance.py:341} INFO - ::group::Post task execution logs
[2025-02-26T15:43:06.714+0000] {standard_task_runner.py:124} ERROR - Failed to execute job 42 for task clean_data_task (module 'great_expectations' has no attribute 'from_pandas'; 115)
Traceback (most recent call last):
  File "/home/airflow/.local/lib/python3.12/site-packages/airflow/task/task_runner/standard_task_runner.py", line 117, in _start_by_fork
    ret = args.func(args, dag=self.dag)
          ^^^^^^^^^^^^^^^^^^^^^^^^^^^^^
  File "/home/airflow/.local/lib/python3.12/site-packages/airflow/cli/cli_config.py", line 49, in command
    return func(*args, **kwargs)
           ^^^^^^^^^^^^^^^^^^^^^
  File "/home/airflow/.local/lib/python3.12/site-packages/airflow/utils/cli.py", line 116, in wrapper
    return f(*args, **kwargs)
           ^^^^^^^^^^^^^^^^^^
  File "/home/airflow/.local/lib/python3.12/site-packages/airflow/cli/commands/task_command.py", line 483, in task_run
    task_return_code = _run_task_by_selected_method(args, _dag, ti)
                       ^^^^^^^^^^^^^^^^^^^^^^^^^^^^^^^^^^^^^^^^^^^^
  File "/home/airflow/.local/lib/python3.12/site-packages/airflow/cli/commands/task_command.py", line 256, in _run_task_by_selected_method
    return _run_raw_task(args, ti)
           ^^^^^^^^^^^^^^^^^^^^^^^
  File "/home/airflow/.local/lib/python3.12/site-packages/airflow/cli/commands/task_command.py", line 341, in _run_raw_task
    return ti._run_raw_task(
           ^^^^^^^^^^^^^^^^^
  File "/home/airflow/.local/lib/python3.12/site-packages/airflow/utils/session.py", line 97, in wrapper
    return func(*args, session=session, **kwargs)
           ^^^^^^^^^^^^^^^^^^^^^^^^^^^^^^^^^^^^^^
  File "/home/airflow/.local/lib/python3.12/site-packages/airflow/models/taskinstance.py", line 3006, in _run_raw_task
    return _run_raw_task(
           ^^^^^^^^^^^^^^
  File "/home/airflow/.local/lib/python3.12/site-packages/airflow/models/taskinstance.py", line 274, in _run_raw_task
    TaskInstance._execute_task_with_callbacks(
  File "/home/airflow/.local/lib/python3.12/site-packages/airflow/models/taskinstance.py", line 3161, in _execute_task_with_callbacks
    result = self._execute_task(context, task_orig)
             ^^^^^^^^^^^^^^^^^^^^^^^^^^^^^^^^^^^^^^
  File "/home/airflow/.local/lib/python3.12/site-packages/airflow/models/taskinstance.py", line 3185, in _execute_task
    return _execute_task(self, context, task_orig)
           ^^^^^^^^^^^^^^^^^^^^^^^^^^^^^^^^^^^^^^^
  File "/home/airflow/.local/lib/python3.12/site-packages/airflow/models/taskinstance.py", line 768, in _execute_task
    result = _execute_callable(context=context, **execute_callable_kwargs)
             ^^^^^^^^^^^^^^^^^^^^^^^^^^^^^^^^^^^^^^^^^^^^^^^^^^^^^^^^^^^^^
  File "/home/airflow/.local/lib/python3.12/site-packages/airflow/models/taskinstance.py", line 734, in _execute_callable
    return ExecutionCallableRunner(
           ^^^^^^^^^^^^^^^^^^^^^^^^
  File "/home/airflow/.local/lib/python3.12/site-packages/airflow/utils/operator_helpers.py", line 252, in run
    return self.func(*args, **kwargs)
           ^^^^^^^^^^^^^^^^^^^^^^^^^^
  File "/home/airflow/.local/lib/python3.12/site-packages/airflow/models/baseoperator.py", line 424, in wrapper
    return func(self, *args, **kwargs)
           ^^^^^^^^^^^^^^^^^^^^^^^^^^^
  File "/home/airflow/.local/lib/python3.12/site-packages/airflow/operators/python.py", line 238, in execute
    return_value = self.execute_callable()
                   ^^^^^^^^^^^^^^^^^^^^^^^
  File "/home/airflow/.local/lib/python3.12/site-packages/airflow/operators/python.py", line 256, in execute_callable
    return runner.run(*self.op_args, **self.op_kwargs)
           ^^^^^^^^^^^^^^^^^^^^^^^^^^^^^^^^^^^^^^^^^^^
  File "/home/airflow/.local/lib/python3.12/site-packages/airflow/utils/operator_helpers.py", line 252, in run
    return self.func(*args, **kwargs)
           ^^^^^^^^^^^^^^^^^^^^^^^^^^
  File "/opt/airflow/dags/data_cleaning_ecommerce_postgres.py", line 276, in load_and_clean_data
    quality_check_passed = run_data_quality_checks(df_clean)
                           ^^^^^^^^^^^^^^^^^^^^^^^^^^^^^^^^^
  File "/opt/airflow/dags/data_cleaning_ecommerce_postgres.py", line 207, in run_data_quality_checks
    ge_df = ge.from_pandas(df)
            ^^^^^^^^^^^^^^
AttributeError: module 'great_expectations' has no attribute 'from_pandas'
[2025-02-26T15:43:06.759+0000] {local_task_job_runner.py:266} INFO - Task exited with return code 1
[2025-02-26T15:43:06.769+0000] {taskinstance.py:3901} INFO - 0 downstream tasks scheduled from follow-on schedule check
[2025-02-26T15:43:06.770+0000] {local_task_job_runner.py:245} INFO - ::endgroup::
