[2025-02-26T15:00:45.956+0000] {local_task_job_runner.py:123} INFO - ::group::Pre task execution logs
[2025-02-26T15:00:45.963+0000] {taskinstance.py:2614} INFO - Dependencies all met for dep_context=non-requeueable deps ti=<TaskInstance: data_cleaning_ecommerce_postgres.clean_data_task manual__2025-02-26T14:54:30.905458+00:00 [queued]>
[2025-02-26T15:00:45.966+0000] {taskinstance.py:2614} INFO - Dependencies all met for dep_context=requeueable deps ti=<TaskInstance: data_cleaning_ecommerce_postgres.clean_data_task manual__2025-02-26T14:54:30.905458+00:00 [queued]>
[2025-02-26T15:00:45.967+0000] {taskinstance.py:2867} INFO - Starting attempt 3 of 4
[2025-02-26T15:00:45.972+0000] {taskinstance.py:2890} INFO - Executing <Task(PythonOperator): clean_data_task> on 2025-02-26 14:54:30.905458+00:00
[2025-02-26T15:00:45.976+0000] {warnings.py:112} WARNING - /home/***/.local/lib/python3.12/site-packages/***/task/task_runner/standard_task_runner.py:70: DeprecationWarning: This process (pid=112) is multi-threaded, use of fork() may lead to deadlocks in the child.
  pid = os.fork()

[2025-02-26T15:00:45.977+0000] {standard_task_runner.py:72} INFO - Started process 120 to run task
[2025-02-26T15:00:45.978+0000] {standard_task_runner.py:104} INFO - Running: ['***', 'tasks', 'run', 'data_cleaning_ecommerce_postgres', 'clean_data_task', 'manual__2025-02-26T14:54:30.905458+00:00', '--job-id', '15', '--raw', '--subdir', 'DAGS_FOLDER/data_cleaning_ecommerce_postgres.py', '--cfg-path', '/tmp/tmp3c2rwk2v']
[2025-02-26T15:00:45.979+0000] {standard_task_runner.py:105} INFO - Job 15: Subtask clean_data_task
[2025-02-26T15:00:46.003+0000] {task_command.py:467} INFO - Running <TaskInstance: data_cleaning_ecommerce_postgres.clean_data_task manual__2025-02-26T14:54:30.905458+00:00 [running]> on host 7abf5e180a33
[2025-02-26T15:00:46.038+0000] {taskinstance.py:3134} INFO - Exporting env vars: AIRFLOW_CTX_DAG_OWNER='***' AIRFLOW_CTX_DAG_ID='data_cleaning_ecommerce_postgres' AIRFLOW_CTX_TASK_ID='clean_data_task' AIRFLOW_CTX_EXECUTION_DATE='2025-02-26T14:54:30.905458+00:00' AIRFLOW_CTX_TRY_NUMBER='3' AIRFLOW_CTX_DAG_RUN_ID='manual__2025-02-26T14:54:30.905458+00:00'
[2025-02-26T15:00:46.039+0000] {logging_mixin.py:190} INFO - Task instance is in running state
[2025-02-26T15:00:46.039+0000] {logging_mixin.py:190} INFO -  Previous state of the Task instance: queued
[2025-02-26T15:00:46.039+0000] {logging_mixin.py:190} INFO - Current task name:clean_data_task state:running start_date:2025-02-26 15:00:45.964184+00:00
[2025-02-26T15:00:46.040+0000] {logging_mixin.py:190} INFO - Dag name:data_cleaning_ecommerce_postgres and current dag run status:running
[2025-02-26T15:00:46.040+0000] {taskinstance.py:732} INFO - ::endgroup::
[2025-02-26T15:00:46.040+0000] {data_cleaning_ecommerce_postgres.py:246} INFO - Starting e-commerce data cleaning process
[2025-02-26T15:00:46.040+0000] {data_cleaning_ecommerce_postgres.py:61} INFO - Establishing database connection
[2025-02-26T15:00:46.040+0000] {data_cleaning_ecommerce_postgres.py:73} ERROR - Failed to connect to database: connection to server on socket "/var/run/postgresql/.s.PGSQL.5432" failed: No such file or directory
	Is the server running locally and accepting connections on that socket?

[2025-02-26T15:00:46.040+0000] {data_cleaning_ecommerce_postgres.py:278} ERROR - Data cleaning process failed: connection to server on socket "/var/run/postgresql/.s.PGSQL.5432" failed: No such file or directory
	Is the server running locally and accepting connections on that socket?

[2025-02-26T15:00:46.041+0000] {taskinstance.py:3313} ERROR - Task failed with exception
Traceback (most recent call last):
  File "/home/airflow/.local/lib/python3.12/site-packages/airflow/models/taskinstance.py", line 768, in _execute_task
    result = _execute_callable(context=context, **execute_callable_kwargs)
             ^^^^^^^^^^^^^^^^^^^^^^^^^^^^^^^^^^^^^^^^^^^^^^^^^^^^^^^^^^^^^
  File "/home/airflow/.local/lib/python3.12/site-packages/airflow/models/taskinstance.py", line 734, in _execute_callable
    return ExecutionCallableRunner(
           ^^^^^^^^^^^^^^^^^^^^^^^^
  File "/home/airflow/.local/lib/python3.12/site-packages/airflow/utils/operator_helpers.py", line 252, in run
    return self.func(*args, **kwargs)
           ^^^^^^^^^^^^^^^^^^^^^^^^^^
  File "/home/airflow/.local/lib/python3.12/site-packages/airflow/models/baseoperator.py", line 424, in wrapper
    return func(self, *args, **kwargs)
           ^^^^^^^^^^^^^^^^^^^^^^^^^^^
  File "/home/airflow/.local/lib/python3.12/site-packages/airflow/operators/python.py", line 238, in execute
    return_value = self.execute_callable()
                   ^^^^^^^^^^^^^^^^^^^^^^^
  File "/home/airflow/.local/lib/python3.12/site-packages/airflow/operators/python.py", line 256, in execute_callable
    return runner.run(*self.op_args, **self.op_kwargs)
           ^^^^^^^^^^^^^^^^^^^^^^^^^^^^^^^^^^^^^^^^^^^
  File "/home/airflow/.local/lib/python3.12/site-packages/airflow/utils/operator_helpers.py", line 252, in run
    return self.func(*args, **kwargs)
           ^^^^^^^^^^^^^^^^^^^^^^^^^^
  File "/opt/airflow/dags/data_cleaning_ecommerce_postgres.py", line 249, in load_and_clean_data
    conn = get_database_connection()
           ^^^^^^^^^^^^^^^^^^^^^^^^^
  File "/opt/airflow/dags/data_cleaning_ecommerce_postgres.py", line 63, in get_database_connection
    conn = psycopg2.connect(
           ^^^^^^^^^^^^^^^^^
  File "/home/airflow/.local/lib/python3.12/site-packages/psycopg2/__init__.py", line 122, in connect
    conn = _connect(dsn, connection_factory=connection_factory, **kwasync)
           ^^^^^^^^^^^^^^^^^^^^^^^^^^^^^^^^^^^^^^^^^^^^^^^^^^^^^^^^^^^^^^^
psycopg2.OperationalError: connection to server on socket "/var/run/postgresql/.s.PGSQL.5432" failed: No such file or directory
	Is the server running locally and accepting connections on that socket?

[2025-02-26T15:00:46.047+0000] {logging_mixin.py:190} INFO - Task instance in failure state
[2025-02-26T15:00:46.048+0000] {logging_mixin.py:190} INFO - Task start:2025-02-26 15:00:45.964184+00:00 end:2025-02-26 15:00:46.047427+00:00 duration:0.083243
[2025-02-26T15:00:46.048+0000] {logging_mixin.py:190} INFO - Task:<Task(PythonOperator): clean_data_task> dag:<DAG: data_cleaning_ecommerce_postgres> dagrun:<DagRun data_cleaning_ecommerce_postgres @ 2025-02-26 14:54:30.905458+00:00: manual__2025-02-26T14:54:30.905458+00:00, state:running, queued_at: 2025-02-26 15:00:43.474291+00:00. externally triggered: True>
[2025-02-26T15:00:46.048+0000] {logging_mixin.py:190} INFO - Failure caused by connection to server on socket "/var/run/postgresql/.s.PGSQL.5432" failed: No such file or directory
	Is the server running locally and accepting connections on that socket?
[2025-02-26T15:00:46.048+0000] {taskinstance.py:1226} INFO - Marking task as UP_FOR_RETRY. dag_id=data_cleaning_ecommerce_postgres, task_id=clean_data_task, run_id=manual__2025-02-26T14:54:30.905458+00:00, execution_date=20250226T145430, start_date=20250226T150045, end_date=20250226T150046
[2025-02-26T15:00:46.060+0000] {taskinstance.py:341} INFO - ::group::Post task execution logs
[2025-02-26T15:00:46.061+0000] {standard_task_runner.py:124} ERROR - Failed to execute job 15 for task clean_data_task (connection to server on socket "/var/run/postgresql/.s.PGSQL.5432" failed: No such file or directory
	Is the server running locally and accepting connections on that socket?
; 120)
Traceback (most recent call last):
  File "/home/airflow/.local/lib/python3.12/site-packages/airflow/task/task_runner/standard_task_runner.py", line 117, in _start_by_fork
    ret = args.func(args, dag=self.dag)
          ^^^^^^^^^^^^^^^^^^^^^^^^^^^^^
  File "/home/airflow/.local/lib/python3.12/site-packages/airflow/cli/cli_config.py", line 49, in command
    return func(*args, **kwargs)
           ^^^^^^^^^^^^^^^^^^^^^
  File "/home/airflow/.local/lib/python3.12/site-packages/airflow/utils/cli.py", line 116, in wrapper
    return f(*args, **kwargs)
           ^^^^^^^^^^^^^^^^^^
  File "/home/airflow/.local/lib/python3.12/site-packages/airflow/cli/commands/task_command.py", line 483, in task_run
    task_return_code = _run_task_by_selected_method(args, _dag, ti)
                       ^^^^^^^^^^^^^^^^^^^^^^^^^^^^^^^^^^^^^^^^^^^^
  File "/home/airflow/.local/lib/python3.12/site-packages/airflow/cli/commands/task_command.py", line 256, in _run_task_by_selected_method
    return _run_raw_task(args, ti)
           ^^^^^^^^^^^^^^^^^^^^^^^
  File "/home/airflow/.local/lib/python3.12/site-packages/airflow/cli/commands/task_command.py", line 341, in _run_raw_task
    return ti._run_raw_task(
           ^^^^^^^^^^^^^^^^^
  File "/home/airflow/.local/lib/python3.12/site-packages/airflow/utils/session.py", line 97, in wrapper
    return func(*args, session=session, **kwargs)
           ^^^^^^^^^^^^^^^^^^^^^^^^^^^^^^^^^^^^^^
  File "/home/airflow/.local/lib/python3.12/site-packages/airflow/models/taskinstance.py", line 3006, in _run_raw_task
    return _run_raw_task(
           ^^^^^^^^^^^^^^
  File "/home/airflow/.local/lib/python3.12/site-packages/airflow/models/taskinstance.py", line 274, in _run_raw_task
    TaskInstance._execute_task_with_callbacks(
  File "/home/airflow/.local/lib/python3.12/site-packages/airflow/models/taskinstance.py", line 3161, in _execute_task_with_callbacks
    result = self._execute_task(context, task_orig)
             ^^^^^^^^^^^^^^^^^^^^^^^^^^^^^^^^^^^^^^
  File "/home/airflow/.local/lib/python3.12/site-packages/airflow/models/taskinstance.py", line 3185, in _execute_task
    return _execute_task(self, context, task_orig)
           ^^^^^^^^^^^^^^^^^^^^^^^^^^^^^^^^^^^^^^^
  File "/home/airflow/.local/lib/python3.12/site-packages/airflow/models/taskinstance.py", line 768, in _execute_task
    result = _execute_callable(context=context, **execute_callable_kwargs)
             ^^^^^^^^^^^^^^^^^^^^^^^^^^^^^^^^^^^^^^^^^^^^^^^^^^^^^^^^^^^^^
  File "/home/airflow/.local/lib/python3.12/site-packages/airflow/models/taskinstance.py", line 734, in _execute_callable
    return ExecutionCallableRunner(
           ^^^^^^^^^^^^^^^^^^^^^^^^
  File "/home/airflow/.local/lib/python3.12/site-packages/airflow/utils/operator_helpers.py", line 252, in run
    return self.func(*args, **kwargs)
           ^^^^^^^^^^^^^^^^^^^^^^^^^^
  File "/home/airflow/.local/lib/python3.12/site-packages/airflow/models/baseoperator.py", line 424, in wrapper
    return func(self, *args, **kwargs)
           ^^^^^^^^^^^^^^^^^^^^^^^^^^^
  File "/home/airflow/.local/lib/python3.12/site-packages/airflow/operators/python.py", line 238, in execute
    return_value = self.execute_callable()
                   ^^^^^^^^^^^^^^^^^^^^^^^
  File "/home/airflow/.local/lib/python3.12/site-packages/airflow/operators/python.py", line 256, in execute_callable
    return runner.run(*self.op_args, **self.op_kwargs)
           ^^^^^^^^^^^^^^^^^^^^^^^^^^^^^^^^^^^^^^^^^^^
  File "/home/airflow/.local/lib/python3.12/site-packages/airflow/utils/operator_helpers.py", line 252, in run
    return self.func(*args, **kwargs)
           ^^^^^^^^^^^^^^^^^^^^^^^^^^
  File "/opt/airflow/dags/data_cleaning_ecommerce_postgres.py", line 249, in load_and_clean_data
    conn = get_database_connection()
           ^^^^^^^^^^^^^^^^^^^^^^^^^
  File "/opt/airflow/dags/data_cleaning_ecommerce_postgres.py", line 63, in get_database_connection
    conn = psycopg2.connect(
           ^^^^^^^^^^^^^^^^^
  File "/home/airflow/.local/lib/python3.12/site-packages/psycopg2/__init__.py", line 122, in connect
    conn = _connect(dsn, connection_factory=connection_factory, **kwasync)
           ^^^^^^^^^^^^^^^^^^^^^^^^^^^^^^^^^^^^^^^^^^^^^^^^^^^^^^^^^^^^^^^
psycopg2.OperationalError: connection to server on socket "/var/run/postgresql/.s.PGSQL.5432" failed: No such file or directory
	Is the server running locally and accepting connections on that socket?

[2025-02-26T15:00:46.077+0000] {local_task_job_runner.py:266} INFO - Task exited with return code 1
[2025-02-26T15:00:46.086+0000] {taskinstance.py:3901} INFO - 0 downstream tasks scheduled from follow-on schedule check
[2025-02-26T15:00:46.087+0000] {local_task_job_runner.py:245} INFO - ::endgroup::
